<?xml version="1.0" encoding="utf-8"?>
<!-- =================================================================================== -->
<!-- |    This document was autogenerated by xacro from ./src/kuka_barrett_description/urdf/kuka_barrett.xacro | -->
<!-- |    EDITING THIS FILE BY HAND IS NOT RECOMMENDED                                 | -->
<!-- =================================================================================== -->
<robot name="kuka_barrett">
  <material name="Black">
    <color rgba="0.0 0.0 0.0 1.0"/>
  </material>
  <material name="Blue">
    <color rgba="0.0 0.0 0.8 1.0"/>
  </material>
  <material name="Green">
    <color rgba="0.0 0.8 0.0 1.0"/>
  </material>
  <material name="Grey">
    <color rgba="0.4 0.4 0.4 1.0"/>
  </material>
  <material name="Orange">
    <color rgba="1.0 0.423529411765 0.0392156862745 1.0"/>
  </material>
  <material name="Brown">
    <color rgba="0.870588235294 0.811764705882 0.764705882353 1.0"/>
  </material>
  <material name="Red">
    <color rgba="0.8 0.0 0.0 1.0"/>
  </material>
  <material name="White">
    <color rgba="1.0 1.0 1.0 1.0"/>
  </material>
  <!--xacro:include filename="$(find kuka_barrett_description)/urdf/iiwa.transmission.xacro" /-->
  <!-- Fix to world just for testing -->
  <link name="world"/>
  <!--joint between {parent} (world) and custom_base-->
  <joint name="world_custom_base_joint" type="fixed">
    <origin rpy="0 0 0" xyz="0 0 0"/>
    <parent link="world"/>
    <child link="custom_base"/>
  </joint>
  <!-- Robot base -->
  <link name="custom_base">
    <inertial>
      <origin rpy="0 0 0" xyz="0 0 0"/>
      <mass value="10"/>
      <inertia ixx="100" ixy="0" ixz="0" iyy="100" iyz="0" izz="100"/>
    </inertial>
    <visual>
      <origin rpy="0 0 0" xyz="0 0 0.5"/>
      <geometry>
        <box size="0.5 0.5 1"/>
      </geometry>
      <material name="Cyan">
        <color rgba="0 1.0 1.0 1.0"/>
      </material>
    </visual>
    <collision>
      <origin rpy="0 0 0" xyz="0 0 0.5"/>
      <geometry>
        <box size="0.5 0.5 1"/>
      </geometry>
    </collision>
  </link>
  <!--joint between base and link_0-->
  <joint name="custom_base_iiwa_joint" type="fixed">
    <origin rpy="0 0 0" xyz="0 0 1"/>
    <parent link="custom_base"/>
    <child link="iiwa_link_0"/>
  </joint>
  <link name="iiwa_link_0">
    <inertial>
      <origin rpy="0 0 0" xyz="0 0 0"/>
      <mass value="5"/>
      <inertia ixx="0.05" ixy="0" ixz="0" iyy="0.06" iyz="0" izz="0.03"/>
    </inertial>
    <visual>
      <origin rpy="0 0 0" xyz="0 0 0"/>
      <geometry>
        <mesh filename="package://kuka_barrett_description/meshes/iiwa14/visual/link_0.stl"/>
      </geometry>
      <material name="Grey"/>
    </visual>
    <collision>
      <origin rpy="0 0 0" xyz="0 0 0"/>
      <geometry>
        <mesh filename="package://kuka_barrett_description/meshes/iiwa14/collision/link_0.stl"/>
      </geometry>
      <material name="Grey"/>
    </collision>
    <self_collision_checking>
      <origin rpy="0 0 0" xyz="0 0 0"/>
      <geometry>
        <capsule length="0.25" radius="0.15"/>
      </geometry>
    </self_collision_checking>
  </link>
  <!-- joint between link_0 and link_1 -->
  <joint name="iiwa_joint_1" type="revolute">
    <parent link="iiwa_link_0"/>
    <child link="iiwa_link_1"/>
    <origin rpy="0 0 0" xyz="0 0 0.1575"/>
    <axis xyz="0 0 1"/>
    <limit effort="300" lower="-2.96705972839" upper="2.96705972839" velocity="10"/>
    <safety_controller k_position="100" k_velocity="2" soft_lower_limit="-2.93215314335" soft_upper_limit="2.93215314335"/>
    <dynamics damping="0.5"/>
  </joint>
  <link name="iiwa_link_1">
    <inertial>
      <origin rpy="0 0 0" xyz="0 -0.03 0.12"/>
      <mass value="4"/>
      <inertia ixx="0.1" ixy="0" ixz="0" iyy="0.09" iyz="0" izz="0.02"/>
    </inertial>
    <visual>
      <origin rpy="0 0 0" xyz="0 0 0"/>
      <geometry>
        <mesh filename="package://kuka_barrett_description/meshes/iiwa14/visual/link_1.stl"/>
      </geometry>
      <material name="Orange"/>
    </visual>
    <collision>
      <origin rpy="0 0 0" xyz="0 0 0"/>
      <geometry>
        <mesh filename="package://kuka_barrett_description/meshes/iiwa14/collision/link_1.stl"/>
      </geometry>
      <material name="Orange"/>
    </collision>
  </link>
  <!-- joint between link_1 and link_2 -->
  <joint name="iiwa_joint_2" type="revolute">
    <parent link="iiwa_link_1"/>
    <child link="iiwa_link_2"/>
    <origin rpy="1.57079632679   0 3.14159265359" xyz="0 0 0.2025"/>
    <axis xyz="0 0 1"/>
    <limit effort="300" lower="-2.09439510239" upper="2.09439510239" velocity="10"/>
    <safety_controller k_position="100" k_velocity="2" soft_lower_limit="-2.05948851735" soft_upper_limit="2.05948851735"/>
    <dynamics damping="0.5"/>
  </joint>
  <link name="iiwa_link_2">
    <inertial>
      <origin rpy="0 0 0" xyz="0.0003 0.059 0.042"/>
      <mass value="4"/>
      <inertia ixx="0.05" ixy="0" ixz="0" iyy="0.018" iyz="0" izz="0.044"/>
    </inertial>
    <visual>
      <origin rpy="0 0 0" xyz="0 0 0"/>
      <geometry>
        <mesh filename="package://kuka_barrett_description/meshes/iiwa14/visual/link_2.stl"/>
      </geometry>
      <material name="Orange"/>
    </visual>
    <collision>
      <origin rpy="0 0 0" xyz="0 0 0"/>
      <geometry>
        <mesh filename="package://kuka_barrett_description/meshes/iiwa14/collision/link_2.stl"/>
      </geometry>
      <material name="Orange"/>
    </collision>
  </link>
  <!-- joint between link_2 and link_3 -->
  <joint name="iiwa_joint_3" type="revolute">
    <parent link="iiwa_link_2"/>
    <child link="iiwa_link_3"/>
    <origin rpy="1.57079632679 0 3.14159265359" xyz="0 0.2045 0"/>
    <axis xyz="0 0 1"/>
    <limit effort="300" lower="-2.96705972839" upper="2.96705972839" velocity="10"/>
    <safety_controller k_position="100" k_velocity="2" soft_lower_limit="-2.93215314335" soft_upper_limit="2.93215314335"/>
    <dynamics damping="0.5"/>
  </joint>
  <link name="iiwa_link_3">
    <inertial>
      <origin rpy="0 0 0" xyz="0 0.03 0.13"/>
      <mass value="3"/>
      <inertia ixx="0.08" ixy="0" ixz="0" iyy="0.075" iyz="0" izz="0.01"/>
    </inertial>
    <visual>
      <origin rpy="0 0 0" xyz="0 0 0"/>
      <geometry>
        <mesh filename="package://kuka_barrett_description/meshes/iiwa14/visual/link_3.stl"/>
      </geometry>
      <material name="Orange"/>
    </visual>
    <collision>
      <origin rpy="0 0 0" xyz="0 0 0"/>
      <geometry>
        <mesh filename="package://kuka_barrett_description/meshes/iiwa14/collision/link_3.stl"/>
      </geometry>
      <material name="Orange"/>
    </collision>
  </link>
  <!-- joint between link_3 and link_4 -->
  <joint name="iiwa_joint_4" type="revolute">
    <parent link="iiwa_link_3"/>
    <child link="iiwa_link_4"/>
    <origin rpy="1.57079632679 0 0" xyz="0 0 0.2155"/>
    <axis xyz="0 0 1"/>
    <limit effort="300" lower="-2.09439510239" upper="2.09439510239" velocity="10"/>
    <safety_controller k_position="100" k_velocity="2" soft_lower_limit="-2.05948851735" soft_upper_limit="2.05948851735"/>
    <dynamics damping="0.5"/>
  </joint>
  <link name="iiwa_link_4">
    <inertial>
      <origin rpy="0 0 0" xyz="0 0.067 0.034"/>
      <mass value="2.7"/>
      <inertia ixx="0.03" ixy="0" ixz="0" iyy="0.01" iyz="0" izz="0.029"/>
    </inertial>
    <visual>
      <origin rpy="0 0 0" xyz="0 0 0"/>
      <geometry>
        <mesh filename="package://kuka_barrett_description/meshes/iiwa14/visual/link_4.stl"/>
      </geometry>
      <material name="Orange"/>
    </visual>
    <collision>
      <origin rpy="0 0 0" xyz="0 0 0"/>
      <geometry>
        <mesh filename="package://kuka_barrett_description/meshes/iiwa14/collision/link_4.stl"/>
      </geometry>
      <material name="Orange"/>
    </collision>
  </link>
  <!-- joint between link_4 and link_5 -->
  <joint name="iiwa_joint_5" type="revolute">
    <parent link="iiwa_link_4"/>
    <child link="iiwa_link_5"/>
    <origin rpy="-1.57079632679 3.14159265359 0" xyz="0 0.1845 0"/>
    <axis xyz="0 0 1"/>
    <limit effort="300" lower="-2.96705972839" upper="2.96705972839" velocity="10"/>
    <safety_controller k_position="100" k_velocity="2" soft_lower_limit="-2.93215314335" soft_upper_limit="2.93215314335"/>
    <dynamics damping="0.5"/>
  </joint>
  <link name="iiwa_link_5">
    <inertial>
      <origin rpy="0 0 0" xyz="0.0001 0.021 0.076"/>
      <mass value="1.7"/>
      <inertia ixx="0.02" ixy="0" ixz="0" iyy="0.018" iyz="0" izz="0.005"/>
    </inertial>
    <visual>
      <origin rpy="0 0 0" xyz="0 0 0"/>
      <geometry>
        <mesh filename="package://kuka_barrett_description/meshes/iiwa14/visual/link_5.stl"/>
      </geometry>
      <material name="Orange"/>
    </visual>
    <collision>
      <origin rpy="0 0 0" xyz="0 0 0"/>
      <geometry>
        <mesh filename="package://kuka_barrett_description/meshes/iiwa14/collision/link_5.stl"/>
      </geometry>
      <material name="Orange"/>
    </collision>
  </link>
  <!-- joint between link_5 and link_6 -->
  <joint name="iiwa_joint_6" type="revolute">
    <parent link="iiwa_link_5"/>
    <child link="iiwa_link_6"/>
    <origin rpy="1.57079632679 0 0" xyz="0 0 0.2155"/>
    <axis xyz="0 0 1"/>
    <limit effort="300" lower="-2.09439510239" upper="2.09439510239" velocity="10"/>
    <safety_controller k_position="100" k_velocity="2" soft_lower_limit="-2.05948851735" soft_upper_limit="2.05948851735"/>
    <dynamics damping="0.5"/>
  </joint>
  <link name="iiwa_link_6">
    <inertial>
      <origin rpy="0 0 0" xyz="0 0.0006 0.0004"/>
      <mass value="1.8"/>
      <inertia ixx="0.005" ixy="0" ixz="0" iyy="0.0036" iyz="0" izz="0.0047"/>
    </inertial>
    <visual>
      <origin rpy="0 0 0" xyz="0 0 0"/>
      <geometry>
        <mesh filename="package://kuka_barrett_description/meshes/iiwa14/visual/link_6.stl"/>
      </geometry>
      <material name="Orange"/>
    </visual>
    <collision>
      <origin rpy="0 0 0" xyz="0 0 0"/>
      <geometry>
        <mesh filename="package://kuka_barrett_description/meshes/iiwa14/collision/link_6.stl"/>
      </geometry>
      <material name="Orange"/>
    </collision>
  </link>
  <!-- joint between link_6 and link_7 -->
  <joint name="iiwa_joint_7" type="revolute">
    <parent link="iiwa_link_6"/>
    <child link="iiwa_link_7"/>
    <origin rpy="-1.57079632679 3.14159265359 0" xyz="0 0.081 0"/>
    <axis xyz="0 0 1"/>
    <limit effort="300" lower="-3.05432619099" upper="3.05432619099" velocity="10"/>
    <safety_controller k_position="100" k_velocity="2" soft_lower_limit="-3.01941960595" soft_upper_limit="3.01941960595"/>
    <dynamics damping="0.5"/>
  </joint>
  <link name="iiwa_link_7">
    <inertial>
      <origin rpy="0 0 0" xyz="0 0 0.02"/>
      <mass value="0.3"/>
      <inertia ixx="0.001" ixy="0" ixz="0" iyy="0.001" iyz="0" izz="0.001"/>
    </inertial>
    <visual>
      <origin rpy="0 0 0" xyz="0 0 0"/>
      <geometry>
        <mesh filename="package://kuka_barrett_description/meshes/iiwa14/visual/link_7.stl"/>
      </geometry>
      <material name="Grey"/>
    </visual>
    <collision>
      <origin rpy="0 0 0" xyz="0 0 0"/>
      <geometry>
        <mesh filename="package://kuka_barrett_description/meshes/iiwa14/collision/link_7.stl"/>
      </geometry>
      <material name="Grey"/>
    </collision>
  </link>
  <joint name="iiwa_joint_ee" type="fixed">
    <parent link="iiwa_link_7"/>
    <child link="iiwa_link_ee"/>
    <origin rpy="0 0 0" xyz="0 0 0"/>
  </joint>
  <link name="iiwa_link_ee">
    </link>
  <!-- Load Gazebo lib and set the robot namespace -->
  <!--gazebo>
      <plugin name="gazebo_ros_control" filename="libgazebo_ros_control.so">
        <robotNamespace>/${robot_name}</robotNamespace>
      </plugin>
    </gazebo-->
  <!-- robot_base -->
  <gazebo reference="custom_base">
    <material>Gazebo/Grey</material>
    <mu1>0.2</mu1>
    <mu2>0.2</mu2>
  </gazebo>
  <!-- Link0 -->
  <gazebo reference="iiwa_link_0">
    <material>Gazebo/Grey</material>
    <mu1>0.2</mu1>
    <mu2>0.2</mu2>
  </gazebo>
  <!-- Link1 -->
  <gazebo reference="iiwa_link_1">
    <material>Gazebo/Orange</material>
    <mu1>0.2</mu1>
    <mu2>0.2</mu2>
  </gazebo>
  <!-- Link2 -->
  <gazebo reference="iiwa_link_2">
    <material>Gazebo/Orange</material>
    <mu1>0.2</mu1>
    <mu2>0.2</mu2>
  </gazebo>
  <!-- Link3 -->
  <gazebo reference="iiwa_link_3">
    <material>Gazebo/Orange</material>
    <mu1>0.2</mu1>
    <mu2>0.2</mu2>
  </gazebo>
  <!-- Link4 -->
  <gazebo reference="iiwa_link_4">
    <material>Gazebo/Orange</material>
    <mu1>0.2</mu1>
    <mu2>0.2</mu2>
  </gazebo>
  <!-- Link5 -->
  <gazebo reference="iiwa_link_5">
    <material>Gazebo/Orange</material>
    <mu1>0.2</mu1>
    <mu2>0.2</mu2>
  </gazebo>
  <!-- Link6 -->
  <gazebo reference="iiwa_link_6">
    <material>Gazebo/Orange</material>
    <mu1>0.2</mu1>
    <mu2>0.2</mu2>
  </gazebo>
  <!-- Link7 -->
  <gazebo reference="iiwa_link_7">
    <material>Gazebo/Grey</material>
    <mu1>0.2</mu1>
    <mu2>0.2</mu2>
  </gazebo>
  <transmission name="iiwa_tran_1">
    <robotNamespace>/iiwa</robotNamespace>
    <type>transmission_interface/SimpleTransmission</type>
    <joint name="iiwa_joint_1">
      <hardwareInterface>PositionJointInterface</hardwareInterface>
    </joint>
    <actuator name="iiwa_motor_1">
      <hardwareInterface>PositionJointInterface</hardwareInterface>
      <mechanicalReduction>1</mechanicalReduction>
    </actuator>
  </transmission>
  <transmission name="iiwa_tran_2">
    <robotNamespace>/iiwa</robotNamespace>
    <type>transmission_interface/SimpleTransmission</type>
    <joint name="iiwa_joint_2">
      <hardwareInterface>PositionJointInterface</hardwareInterface>
    </joint>
    <actuator name="iiwa_motor_2">
      <hardwareInterface>PositionJointInterface</hardwareInterface>
      <mechanicalReduction>1</mechanicalReduction>
    </actuator>
  </transmission>
  <transmission name="iiwa_tran_3">
    <robotNamespace>/iiwa</robotNamespace>
    <type>transmission_interface/SimpleTransmission</type>
    <joint name="iiwa_joint_3">
      <hardwareInterface>PositionJointInterface</hardwareInterface>
    </joint>
    <actuator name="iiwa_motor_3">
      <hardwareInterface>PositionJointInterface</hardwareInterface>
      <mechanicalReduction>1</mechanicalReduction>
    </actuator>
  </transmission>
  <transmission name="iiwa_tran_4">
    <robotNamespace>/iiwa</robotNamespace>
    <type>transmission_interface/SimpleTransmission</type>
    <joint name="iiwa_joint_4">
      <hardwareInterface>PositionJointInterface</hardwareInterface>
    </joint>
    <actuator name="iiwa_motor_4">
      <hardwareInterface>PositionJointInterface</hardwareInterface>
      <mechanicalReduction>1</mechanicalReduction>
    </actuator>
  </transmission>
  <transmission name="iiwa_tran_5">
    <robotNamespace>/iiwa</robotNamespace>
    <type>transmission_interface/SimpleTransmission</type>
    <joint name="iiwa_joint_5">
      <hardwareInterface>PositionJointInterface</hardwareInterface>
    </joint>
    <actuator name="iiwa_motor_5">
      <hardwareInterface>PositionJointInterface</hardwareInterface>
      <mechanicalReduction>1</mechanicalReduction>
    </actuator>
  </transmission>
  <transmission name="iiwa_tran_6">
    <robotNamespace>/iiwa</robotNamespace>
    <type>transmission_interface/SimpleTransmission</type>
    <joint name="iiwa_joint_6">
      <hardwareInterface>PositionJointInterface</hardwareInterface>
    </joint>
    <actuator name="iiwa_motor_6">
      <hardwareInterface>PositionJointInterface</hardwareInterface>
      <mechanicalReduction>1</mechanicalReduction>
    </actuator>
  </transmission>
  <transmission name="iiwa_tran_7">
    <robotNamespace>/iiwa</robotNamespace>
    <type>transmission_interface/SimpleTransmission</type>
    <joint name="iiwa_joint_7">
      <hardwareInterface>PositionJointInterface</hardwareInterface>
    </joint>
    <actuator name="iiwa_motor_7">
      <hardwareInterface>PositionJointInterface</hardwareInterface>
      <mechanicalReduction>1</mechanicalReduction>
    </actuator>
  </transmission>
  <joint name="bh_base_joint" type="fixed">
    <origin rpy="0 0 0" xyz="0 0 0"/>
    <parent link="iiwa_link_ee"/>
    <child link="bh_base_link"/>
  </joint>
  <!-- HAND BASE_LINK (RED) -->
  <link name="bh_base_link">
    <inertial>
      <mass value="1.0"/>
      <origin xyz="0 0 0"/>
      <inertia ixx="1.0" ixy="0.0" ixz="0.0" iyy="1.0" iyz="0.0" izz="1.0"/>
    </inertial>
    <visual>
      <origin rpy="0 0 0" xyz="0 0 0"/>
      <geometry>
        <mesh filename="package://kuka_barrett_description/meshes/palm_282.dae"/>
      </geometry>
      <material name="Grey">
        <color rgba="0.75 0.75 0.75 1.0"/>
      </material>
    </visual>
    <collision>
      <origin rpy="0 0 0 " xyz="0 0 0"/>
      <geometry>
        <mesh filename="package://kuka_barrett_description/meshes/palm_282.dae"/>
      </geometry>
      <contact_coefficients kd="1.0" kp="1000.0" mu="0"/>
    </collision>
  </link>
  <!-- finger 3 -->
  <!-- finger 31 link -->
  <link name="bh_finger_31_link">
    <inertial>
      <mass value="0.1"/>
      <origin rpy="0 0 0" xyz="-0.046 0 0"/>
      <inertia ixx="0.01" ixy="0" ixz="0" iyy="0.01" iyz="0" izz="0.01"/>
    </inertial>
    <visual>
      <origin rpy="0 0 0" xyz="-0.04 0 0"/>
      <geometry>
        <mesh filename="package://kuka_barrett_description/meshes/knuckle_fixed.dae"/>
      </geometry>
      <material name="Black"/>
    </visual>
    <collision>
      <origin rpy="0 0 0" xyz="-0.04 0 0"/>
      <geometry>
        <mesh filename="package://kuka_barrett_description/meshes/knuckle_fixed.dae"/>
      </geometry>
      <contact_coefficients kd="1.0" kp="1000.0" mu="0"/>
    </collision>
  </link>
  <!-- joint between BH_palm_link and BH_finger_31_link -->
  <!-- finger3 is the center finger and is fixed -->
  <joint name="bh_j31_joint" type="fixed">
    <parent link="bh_base_link"/>
    <child link="bh_finger_31_link"/>
    <origin rpy="0 0 -1.570796327" xyz="0 0 0.0252"/>
  </joint>
  <!-- finger 32 link -->
  <link name="bh_finger_32_link">
    <inertial>
      <mass value="0.1"/>
      <origin rpy="0 0 0" xyz="0 0 0"/>
      <inertia ixx="0.01" ixy="0" ixz="0" iyy="0.01" iyz="0" izz="0.01"/>
    </inertial>
    <visual>
      <origin rpy="0 0 0" xyz="0 0 0"/>
      <geometry>
        <mesh filename="package://kuka_barrett_description/meshes/finger.dae"/>
      </geometry>
      <material name="Blue"/>
    </visual>
    <collision>
      <origin rpy="0 0 0" xyz="0 0 0"/>
      <geometry>
        <mesh filename="package://kuka_barrett_description/meshes/finger.dae"/>
      </geometry>
      <contact_coefficients kd="1.0" kp="1000.0" mu="0"/>
    </collision>
  </link>
  <gazebo reference="bh_finger_32_link">
    <mu1>10</mu1>
    <mu2>10</mu2>
    <minDepth>0.01</minDepth>
    <collision name="bh_finger_32_link_collision">
      <surface>
        <friction>
          <ode>
            <slip1>1</slip1>
            <slip2>1</slip2>
          </ode>
        </friction>
      </surface>
    </collision>
    <material>Gazebo/Black</material>
  </gazebo>
  <!-- joint between BH_finger_31_link and BH_finger_32_link -->
  <joint name="bh_j32_joint" type="revolute">
    <parent link="bh_finger_31_link"/>
    <child link="bh_finger_32_link"/>
    <origin rpy="1.5708 -8.8281E-17 0" xyz="-0.05 0 0.0339"/>
    <axis xyz="0 0 -1"/>
    <limit effort="30.0" lower="0.0" upper="2.44" velocity="2.0"/>
    <dynamics damping="100.0" friction="1.0"/>
  </joint>
  <transmission name="bh_j32_transmission">
    <type>transmission_interface/SimpleTransmission</type>
    <joint name="bh_j32_joint">
      <hardwareInterface>PositionJointInterface</hardwareInterface>
    </joint>
    <actuator name="bh_j32">
      <hardwareInterface>PositionJointInterface</hardwareInterface>
      <mechanicalReduction>1</mechanicalReduction>
      <motorTorqueConstant>1</motorTorqueConstant>
    </actuator>
  </transmission>
  <!-- finger 33 link -->
  <link name="bh_finger_33_link">
    <inertial>
      <mass value="0.1"/>
      <origin rpy="0 0 0" xyz="0 0 0"/>
      <inertia ixx="0.01" ixy="0" ixz="0" iyy="0.01" iyz="0" izz="0.01"/>
    </inertial>
    <visual>
      <origin rpy="0 0 0" xyz="0 0 0"/>
      <geometry>
        <mesh filename="package://kuka_barrett_description/meshes/finger_tip.dae"/>
      </geometry>
      <material name="Blue"/>
    </visual>
    <collision>
      <origin rpy="0 0 0" xyz="0 0 0"/>
      <geometry>
        <mesh filename="package://kuka_barrett_description/meshes/finger_tip.dae"/>
      </geometry>
      <contact_coefficients kd="1.0" kp="1000.0" mu="0"/>
    </collision>
  </link>
  <gazebo reference="bh_finger_33_link">
    <mu1>10</mu1>
    <mu2>10</mu2>
    <minDepth>0.01</minDepth>
    <collision name="bh_finger_33_link_collision">
      <surface>
        <friction>
          <ode>
            <slip1>1</slip1>
            <slip2>1</slip2>
          </ode>
        </friction>
      </surface>
    </collision>
    <material>Gazebo/Black</material>
  </gazebo>
  <!-- joint between BH_finger_32_link and BH_finger_33_link -->
  <joint name="bh_j33_joint" type="revolute">
    <parent link="bh_finger_32_link"/>
    <child link="bh_finger_33_link"/>
    <origin rpy="0 0 0" xyz="-0.069936 0.003 0"/>
    <axis xyz="0 0 -1"/>
    <limit effort="30.0" lower="0.0" upper="0.84" velocity="2.0"/>
    <dynamics damping="100.0" friction="1.0"/>
  </joint>
  <transmission name="bh_j33_transmission">
    <type>transmission_interface/SimpleTransmission</type>
    <joint name="bh_j33_joint">
      <hardwareInterface>PositionJointInterface</hardwareInterface>
    </joint>
    <actuator name="bh_j33">
      <hardwareInterface>PositionJointInterface</hardwareInterface>
      <mechanicalReduction>1</mechanicalReduction>
      <motorTorqueConstant>1</motorTorqueConstant>
    </actuator>
  </transmission>
  <!-- finger 1 -->
  <!-- finger 11 link -->
  <link name="bh_finger_11_link">
    <inertial>
      <mass value="0.1"/>
      <origin rpy="0 0 0" xyz="-0.046 0 0"/>
      <inertia ixx="0.01" ixy="0" ixz="0" iyy="0.01" iyz="0" izz="0.01"/>
    </inertial>
    <visual>
      <origin rpy="0 0 0" xyz="0 0 0"/>
      <geometry>
        <mesh filename="package://kuka_barrett_description/meshes/knuckle.dae"/>
      </geometry>
      <material name="Green"/>
    </visual>
    <collision>
      <origin rpy="0 0 0" xyz="0 0 0"/>
      <geometry>
        <mesh filename="package://kuka_barrett_description/meshes/knuckle.dae"/>
      </geometry>
    </collision>
  </link>
  <!-- joint between BH_palm_link and BH_finger_11_link -->
  <joint name="bh_j11_joint" type="revolute">
    <parent link="bh_base_link"/>
    <child link="bh_finger_11_link"/>
    <origin rpy="0 0 1.5708" xyz="-0.025 0 0.0252"/>
    <axis xyz="0 0 -1"/>
    <limit effort="30.0" lower="0" upper="3.1416" velocity="2.0"/>
    <dynamics damping="100.0" friction="1.0"/>
  </joint>
  <transmission name="bh_j11_transmission">
    <type>transmission_interface/SimpleTransmission</type>
    <joint name="bh_j11_joint">
      <hardwareInterface>PositionJointInterface</hardwareInterface>
    </joint>
    <actuator name="bh_j11">
      <hardwareInterface>PositionJointInterface</hardwareInterface>
      <mechanicalReduction>1</mechanicalReduction>
      <motorTorqueConstant>1</motorTorqueConstant>
    </actuator>
  </transmission>
  <!-- finger 12 link -->
  <link name="bh_finger_12_link">
    <inertial>
      <mass value="0.1"/>
      <origin rpy="0 0 0" xyz="0 0 0"/>
      <inertia ixx="0.01" ixy="0" ixz="0" iyy="0.01" iyz="0" izz="0.01"/>
    </inertial>
    <visual>
      <origin rpy="0 0 0" xyz="0 0 0"/>
      <geometry>
        <mesh filename="package://kuka_barrett_description/meshes/finger.dae"/>
      </geometry>
      <material name="Blue"/>
    </visual>
    <collision>
      <origin rpy="0 0 0" xyz="0 0 0"/>
      <geometry>
        <mesh filename="package://kuka_barrett_description/meshes/finger.dae"/>
      </geometry>
      <contact_coefficients kd="1.0" kp="1000.0" mu="0"/>
    </collision>
  </link>
  <gazebo reference="bh_finger_12_link">
    <mu1>10</mu1>
    <mu2>10</mu2>
    <minDepth>0.01</minDepth>
    <collision name="bh_finger_12_link_collision">
      <surface>
        <friction>
          <ode>
            <slip1>1</slip1>
            <slip2>1</slip2>
          </ode>
        </friction>
      </surface>
    </collision>
    <material>Gazebo/Black</material>
  </gazebo>
  <!-- joint between BH_finger_11_link and BH_finger_12_link -->
  <joint name="bh_j12_joint" type="revolute">
    <parent link="bh_finger_11_link"/>
    <child link="bh_finger_12_link"/>
    <origin rpy="1.5708 0 0" xyz="-0.05 0 0.0339"/>
    <axis xyz="0 0 -1"/>
    <limit effort="30.0" lower="0.0" upper="2.44" velocity="2.0"/>
    <dynamics damping="100.0" friction="1.0"/>
  </joint>
  <transmission name="bh_j12_transmission">
    <type>transmission_interface/SimpleTransmission</type>
    <joint name="bh_j12_joint">
      <hardwareInterface>PositionJointInterface</hardwareInterface>
    </joint>
    <actuator name="bh_j12">
      <hardwareInterface>PositionJointInterface</hardwareInterface>
      <mechanicalReduction>1</mechanicalReduction>
      <motorTorqueConstant>1</motorTorqueConstant>
    </actuator>
  </transmission>
  <!-- finger 13 link -->
  <link name="bh_finger_13_link">
    <inertial>
      <mass value="0.1"/>
      <origin rpy="0 0 0" xyz="0 0 0"/>
      <inertia ixx="0.01" ixy="0" ixz="0" iyy="0.01" iyz="0" izz="0.01"/>
    </inertial>
    <visual>
      <origin rpy="0 0 0" xyz="0 0 0"/>
      <geometry>
        <mesh filename="package://kuka_barrett_description/meshes/finger_tip.dae"/>
      </geometry>
      <material name="Blue"/>
    </visual>
    <collision>
      <origin rpy="0 0 0" xyz="0 0 0"/>
      <geometry>
        <mesh filename="package://kuka_barrett_description/meshes/finger_tip.dae"/>
      </geometry>
      <contact_coefficients kd="1.0" kp="1000.0" mu="0"/>
    </collision>
  </link>
  <gazebo reference="bh_finger_13_link">
    <mu1>10</mu1>
    <mu2>10</mu2>
    <minDepth>0.01</minDepth>
    <collision name="bh_finger_13_link_collision">
      <surface>
        <friction>
          <ode>
            <slip1>1</slip1>
            <slip2>1</slip2>
          </ode>
        </friction>
      </surface>
    </collision>
    <material>Gazebo/Black</material>
  </gazebo>
  <!-- joint between BH_finger_12_link and BH_finger_13_link -->
  <joint name="bh_j13_joint" type="revolute">
    <parent link="bh_finger_12_link"/>
    <child link="bh_finger_13_link"/>
    <origin rpy="0 0 0" xyz="-0.069936 0.003 0"/>
    <axis xyz="0 0 -1"/>
    <limit effort="30.0" lower="0.0" upper="0.84" velocity="2.0"/>
    <dynamics damping="100.0" friction="1.0"/>
  </joint>
  <transmission name="bh_j13_transmission">
    <type>transmission_interface/SimpleTransmission</type>
    <joint name="bh_j13_joint">
      <hardwareInterface>PositionJointInterface</hardwareInterface>
    </joint>
    <actuator name="bh_j13">
      <hardwareInterface>PositionJointInterface</hardwareInterface>
      <mechanicalReduction>1</mechanicalReduction>
      <motorTorqueConstant>1</motorTorqueConstant>
    </actuator>
  </transmission>
  <!-- finger 2 -->
  <!-- finger 21 link -->
  <link name="bh_finger_21_link">
    <inertial>
      <mass value="0.1"/>
      <origin rpy="0 0 0" xyz="-0.046 0 0"/>
      <inertia ixx="0.01" ixy="0" ixz="0" iyy="0.01" iyz="0" izz="0.01"/>
    </inertial>
    <visual>
      <origin rpy="0 0 0" xyz="0 0 0"/>
      <geometry>
        <mesh filename="package://kuka_barrett_description/meshes/knuckle.dae"/>
      </geometry>
      <material name="Green"/>
    </visual>
    <collision>
      <origin rpy="0 0 0" xyz="0 0 0"/>
      <geometry>
        <mesh filename="package://kuka_barrett_description/meshes/knuckle.dae"/>
      </geometry>
    </collision>
  </link>
  <!-- joint between BH_palm_link and BH_finger_21_link -->
  <joint name="bh_j21_joint" type="revolute">
    <parent link="bh_base_link"/>
    <child link="bh_finger_21_link"/>
    <origin rpy="0 0 1.5708" xyz="0.025 0 0.0252"/>
    <axis xyz="0 0 1"/>
    <limit effort="30.0" lower="0" upper="3.1416" velocity="2.0"/>
    <dynamics damping="100.0" friction="1.0"/>
    <!-- joint_21 should mimic joint_11 becase that is how Barrett Hand robot works  -->
    <!--mimic joint="${name}_j11_joint" multiplier="1"/-->
  </joint>
  <transmission name="bh_j21_transmission">
    <type>transmission_interface/SimpleTransmission</type>
    <joint name="bh_j21_joint">
      <hardwareInterface>PositionJointInterface</hardwareInterface>
    </joint>
    <actuator name="bh_j21">
      <hardwareInterface>PositionJointInterface</hardwareInterface>
      <mechanicalReduction>1</mechanicalReduction>
      <motorTorqueConstant>1</motorTorqueConstant>
    </actuator>
  </transmission>
  <!-- finger 12 link -->
  <link name="bh_finger_22_link">
    <inertial>
      <mass value="0.1"/>
      <origin rpy="0 0 0" xyz="0 0 0"/>
      <inertia ixx="0.01" ixy="0" ixz="0" iyy="0.01" iyz="0" izz="0.01"/>
    </inertial>
    <visual>
      <origin rpy="0 0 0" xyz="0 0 0"/>
      <geometry>
        <mesh filename="package://kuka_barrett_description/meshes/finger.dae"/>
      </geometry>
      <material name="Blue"/>
    </visual>
    <collision>
      <origin rpy="0 0 0" xyz="0 0 0"/>
      <geometry>
        <mesh filename="package://kuka_barrett_description/meshes/finger.dae"/>
      </geometry>
      <contact_coefficients kd="1.0" kp="1000.0" mu="0"/>
    </collision>
  </link>
  <gazebo reference="bh_finger_22_link">
    <mu1>10</mu1>
    <mu2>10</mu2>
    <minDepth>0.01</minDepth>
    <collision name="bh_finger_22_link_collision">
      <surface>
        <friction>
          <ode>
            <slip1>1</slip1>
            <slip2>1</slip2>
          </ode>
        </friction>
      </surface>
    </collision>
    <material>Gazebo/Black</material>
  </gazebo>
  <!-- joint between BH_finger_21_link and BH_finger_22_link -->
  <joint name="bh_j22_joint" type="revolute">
    <parent link="bh_finger_21_link"/>
    <child link="bh_finger_22_link"/>
    <origin rpy="1.5708 -8.8281E-17 0" xyz="-0.05 0 0.0339"/>
    <axis xyz="0 0 -1"/>
    <limit effort="30.0" lower="0.0" upper="2.44" velocity="2.0"/>
    <dynamics damping="100.0" friction="1.0"/>
  </joint>
  <transmission name="bh_j22_transmission">
    <type>transmission_interface/SimpleTransmission</type>
    <joint name="bh_j22_joint">
      <hardwareInterface>PositionJointInterface</hardwareInterface>
    </joint>
    <actuator name="bh_j22">
      <hardwareInterface>PositionJointInterface</hardwareInterface>
      <mechanicalReduction>1</mechanicalReduction>
      <motorTorqueConstant>1</motorTorqueConstant>
    </actuator>
  </transmission>
  <!-- finger 23 link -->
  <link name="bh_finger_23_link">
    <inertial>
      <mass value="0.1"/>
      <origin rpy="0 0 0" xyz="0 0 0"/>
      <inertia ixx="0.01" ixy="0" ixz="0" iyy="0.01" iyz="0" izz="0.01"/>
    </inertial>
    <visual>
      <origin rpy="0 0 0" xyz="0 0 0"/>
      <geometry>
        <mesh filename="package://kuka_barrett_description/meshes/finger_tip.dae"/>
      </geometry>
      <material name="Blue"/>
    </visual>
    <collision>
      <origin rpy="0 0 0" xyz="0 0 0"/>
      <geometry>
        <mesh filename="package://kuka_barrett_description/meshes/finger_tip.dae"/>
      </geometry>
      <contact_coefficients kd="1.0" kp="1000.0" mu="0"/>
    </collision>
  </link>
  <gazebo reference="bh_finger_23_link">
    <mu1>10</mu1>
    <mu2>10</mu2>
    <minDepth>0.01</minDepth>
    <collision name="bh_finger_23_link_collision">
      <surface>
        <friction>
          <ode>
            <slip1>1</slip1>
            <slip2>1</slip2>
          </ode>
        </friction>
      </surface>
    </collision>
    <material>Gazebo/Black</material>
  </gazebo>
  <!-- joint between BH_finger_22_link and BH_finger_23_link -->
  <joint name="bh_j23_joint" type="revolute">
    <parent link="bh_finger_22_link"/>
    <child link="bh_finger_23_link"/>
    <origin rpy="0 0 0" xyz="-0.069936 0.003 0"/>
    <axis xyz="0 0 -1"/>
    <limit effort="30.0" lower="0.0" upper="0.84" velocity="2.0"/>
    <dynamics damping="100.0" friction="1.0"/>
  </joint>
  <transmission name="bh_j23_transmission">
    <type>transmission_interface/SimpleTransmission</type>
    <joint name="bh_j23_joint">
      <hardwareInterface>PositionJointInterface</hardwareInterface>
    </joint>
    <actuator name="bh_j23">
      <hardwareInterface>PositionJointInterface</hardwareInterface>
      <mechanicalReduction>1</mechanicalReduction>
      <motorTorqueConstant>1</motorTorqueConstant>
    </actuator>
  </transmission>
  <!-- ros_control plugin -->
  <!--gazebo>
			<plugin name="ros_control" filename="libgazebo_ros_control.so">
			   <robotNamespace>/${name}</robotNamespace>
			   <controlPeriod>0.001</controlPeriod>
			   <robotSimType>gazebo_ros_control/DefaultRobotHWSim</robotSimType>
			</plugin>
		</gazebo-->
  <gazebo reference="bh_base_link">
    <material>Gazebo/White</material>
    <turnGravityOff>false</turnGravityOff>
  </gazebo>
  <gazebo reference="bh_finger_31_link">
    <material>Gazebo/Grey</material>
    <turnGravityOff>false</turnGravityOff>
  </gazebo>
  <gazebo reference="bh_finger_32_link">
    <material>Gazebo/Grey</material>
    <turnGravityOff>false</turnGravityOff>
  </gazebo>
  <gazebo reference="bh_finger_33_link">
    <material>Gazebo/Grey</material>
    <turnGravityOff>false</turnGravityOff>
  </gazebo>
  <gazebo reference="bh_finger_11_link">
    <material>Gazebo/Grey</material>
    <turnGravityOff>false</turnGravityOff>
  </gazebo>
  <gazebo reference="bh_finger_12_link">
    <material>Gazebo/Grey</material>
    <turnGravityOff>false</turnGravityOff>
  </gazebo>
  <gazebo reference="bh_finger_13_link">
    <material>Gazebo/Grey</material>
    <turnGravityOff>false</turnGravityOff>
  </gazebo>
  <gazebo reference="bh_finger_21_link">
    <material>Gazebo/Grey</material>
    <turnGravityOff>false</turnGravityOff>
  </gazebo>
  <gazebo reference="bh_finger_22_link">
    <material>Gazebo/Grey</material>
    <turnGravityOff>false</turnGravityOff>
  </gazebo>
  <gazebo reference="bh_finger_23_link">
    <material>Gazebo/Grey</material>
    <turnGravityOff>false</turnGravityOff>
  </gazebo>
  <!-- Left camera -->
  <joint name="camera_joint1" type="fixed">
    <axis xyz="0 1 0"/>
    <origin rpy="0 -1.57 0" xyz="-0.08 -0.02 0"/>
    <parent link="iiwa_link_ee"/>
    <child link="camera_link1"/>
    <mimic joint="bh_base_joint" multiplier="1" offset="0"/>
  </joint>
  <link name="camera_link1">
    <collision>
      <origin rpy="0 0 0" xyz="0 0 0"/>
      <geometry>
        <box size="0.02 0.04 0.04"/>
      </geometry>
    </collision>
    <visual>
      <origin rpy="0 0 0" xyz="0 0 0"/>
      <geometry>
        <box size="0.02 0.04 0.04"/>
      </geometry>
      <material name="red"/>
    </visual>
    <inertial>
      <mass value="1e-5"/>
      <origin rpy="0 0 0" xyz="0 0 0"/>
      <inertia ixx="1e-6" ixy="0" ixz="0" iyy="1e-6" iyz="0" izz="1e-6"/>
    </inertial>
    <kinematic>1</kinematic>
  </link>
  <!-- Right camera -->
  <joint name="camera_joint2" type="fixed">
    <axis xyz="0 1 0"/>
    <origin rpy="0 -1.57 0" xyz="-0.08 0.02 0"/>
    <parent link="iiwa_link_ee"/>
    <child link="camera_link2"/>
    <mimic joint="bh_base_joint" multiplier="1" offset="0"/>
  </joint>
  <link name="camera_link2">
    <collision>
      <origin rpy="0 0 0" xyz="0 0 0"/>
      <geometry>
        <box size="0.02 0.04 0.04"/>
      </geometry>
    </collision>
    <visual>
      <origin rpy="0 0 0" xyz="0 0 0"/>
      <geometry>
        <box size="0.02 0.04 0.04"/>
      </geometry>
      <material name="blue"/>
    </visual>
    <inertial>
      <mass value="1e-5"/>
      <origin rpy="0 0 0" xyz="0 0 0"/>
      <inertia ixx="1e-6" ixy="0" ixz="0" iyy="1e-6" iyz="0" izz="1e-6"/>
    </inertial>
    <kinematic>1</kinematic>
  </link>
  <gazebo reference="camera_link1">
    <material>Gazebo/Red</material>
    <sensor name="camera1" type="camera">
      <update_rate>30.0</update_rate>
      <camera name="head">
        <horizontal_fov>1.3962634</horizontal_fov>
        <image>
          <width>1280</width>
          <height>720</height>
          <format>R8G8B8</format>
        </image>
        <clip>
          <near>0.02</near>
          <far>300</far>
        </clip>
        <noise>
          <type>gaussian</type>
          <!-- Noise is sampled independently per pixel on each frame.
                    That pixel's noise value is added to each of its color
                    channels, which at that point lie in the range [0,1]. -->
          <mean>0.0</mean>
          <stddev>0.007</stddev>
        </noise>
      </camera>
      <plugin filename="libgazebo_ros_camera.so" name="camera_controller">
        <alwaysOn>true</alwaysOn>
        <updateRate>0.0</updateRate>
        <cameraName>barrett/camera1</cameraName>
        <imageTopicName>image_raw</imageTopicName>
        <cameraInfoTopicName>camera_info</cameraInfoTopicName>
        <frameName>camera_link1</frameName>
        <hackBaseline>0.07</hackBaseline>
        <distortionK1>0.0</distortionK1>
        <distortionK2>0.0</distortionK2>
        <distortionK3>0.0</distortionK3>
        <distortionT1>0.0</distortionT1>
        <distortionT2>0.0</distortionT2>
        <robotNamespace>/</robotNamespace>
      </plugin>
    </sensor>
  </gazebo>
  <gazebo reference="camera_link2">
    <material>Gazebo/Blue</material>
    <sensor name="camera2" type="camera">
      <update_rate>30.0</update_rate>
      <camera name="head">
        <horizontal_fov>1.3962634</horizontal_fov>
        <image>
          <width>1280</width>
          <height>720</height>
          <format>R8G8B8</format>
        </image>
        <clip>
          <near>0.02</near>
          <far>300</far>
        </clip>
        <noise>
          <type>gaussian</type>
          <!-- Noise is sampled independently per pixel on each frame.
                    That pixel's noise value is added to each of its color
                    channels, which at that point lie in the range [0,1]. -->
          <mean>0.0</mean>
          <stddev>0.007</stddev>
        </noise>
      </camera>
      <plugin filename="libgazebo_ros_camera.so" name="camera_controller">
        <alwaysOn>true</alwaysOn>
        <updateRate>0.0</updateRate>
        <cameraName>barrett/camera2</cameraName>
        <imageTopicName>image_raw</imageTopicName>
        <cameraInfoTopicName>camera_info</cameraInfoTopicName>
        <frameName>camera_link2</frameName>
        <hackBaseline>0.07</hackBaseline>
        <distortionK1>0.0</distortionK1>
        <distortionK2>0.0</distortionK2>
        <distortionK3>0.0</distortionK3>
        <distortionT1>0.0</distortionT1>
        <distortionT2>0.0</distortionT2>
        <robotNamespace>/</robotNamespace>
      </plugin>
    </sensor>
  </gazebo>
  <gazebo>
    <plugin filename="libgazebo_ros_control.so" name="gazebo_ros_control">
      <robotNamespace>/</robotNamespace>
    </plugin>
  </gazebo>
</robot>

