<?xml version="1.0" encoding="utf-8"?>

<robot name="surgical_tool">


  <gazebo reference="link3_L">
    <turnGravityOff>true</turnGravityOff>
    <mu1>0.2</mu1>
    <mu2>0.2</mu2>
    <material>Gazebo/Blue</material>
  </gazebo>
  <link name="link3_L">
    <visual>
      <geometry>
        <mesh filename="package://surgical_tools_description/meshes/link3.dae" />
      </geometry>
    </visual>

    <inertial>
      <origin xyz="0 0 0" rpy="0 0 0" />
      <mass value="10" />
      <inertia ixx="10" ixy="0" ixz="0" iyy="10" iyz="0" izz="10" />
    </inertial>

    <collision>
      <geometry>
        <mesh filename="package://surgical_tools_description/meshes/link3.dae" />
      </geometry>
    </collision>
  </link>

  <gazebo reference="instrument_shaft_L">
    <turnGravityOff>true</turnGravityOff>
    <mu1>0.2</mu1>
    <mu2>0.2</mu2>
    <material>Gazebo/Blue</material>
  </gazebo>
  <link name="instrument_shaft_L">
    <visual>
      <geometry>
        <mesh filename="package://surgical_tools_description/meshes/instrument_shaft.dae" />
      </geometry>
    </visual>

    <inertial>
      <origin xyz="0 0 0" rpy="0 0 0" />
      <mass value="10" />
      <inertia ixx="10" ixy="0" ixz="0" iyy="10" iyz="0" izz="10" />
    </inertial>

    <collision>
      <geometry>
        <mesh filename="package://surgical_tools_description/meshes/instrument_shaft.dae" />
      </geometry>
    </collision>

  </link>
  <gazebo reference="wrist_L">
    <turnGravityOff>true</turnGravityOff>
    <mu1>0.2</mu1>
    <mu2>0.2</mu2>
    <material>Gazebo/Blue</material>
  </gazebo>
  <link name="wrist_L">
    <visual>
      <geometry>
        <mesh filename="package://surgical_tools_description/meshes/wrist.dae" />
      </geometry>
    </visual>

    <inertial>
      <origin xyz="0 0 0" rpy="0 0 0" />
      <mass value="1" />
      <inertia ixx="1" ixy="0" ixz="0" iyy="1" iyz="0" izz="1" />
    </inertial>

    <collision>
      <geometry>
        <mesh filename="package://surgical_tools_description/meshes/wrist.dae" />
      </geometry>
    </collision>
  </link>

  <gazebo reference="grasper1_L">
    <turnGravityOff>true</turnGravityOff>
    <implicitSpringDamper>1</implicitSpringDamper>
    <mu1>0.2</mu1>
    <mu2>0.2</mu2>
    <material>Gazebo/Blue</material>
  </gazebo>
  <link name="grasper1_L">
    <visual>
      <geometry>
        <mesh filename="package://surgical_tools_description/meshes/grasper_1.dae" />
      </geometry>
      <origin rpy="0 0 0" xyz="-0.00680 -0.00904 0.00452" />
    </visual>

    <inertial>
      <origin rpy="0 0 0" xyz="-0.00680 -0.00904 0.00452" />
      <mass value="1" />
      <inertia ixx="0" ixy="0" ixz="0" iyy="0" iyz="0" izz="0" />
    </inertial>

    <collision>
      <geometry>
        <mesh filename="package://surgical_tools_description/meshes/grasper_1.dae" />
      </geometry>
      <surface>
        <contact>
          <ode>
            <kp>1000000.0</kp>
            <kd>1.0</kd>
            <minDepth>0.001</minDepth>
          </ode>
        </contact>
      </surface>
      <origin rpy="0 0 0" xyz="-0.00680 -0.00904 0.00452" />
    </collision>

  </link>

  <gazebo reference="grasper2_L">
    <turnGravityOff>true</turnGravityOff>
    <mu1>0.2</mu1>
    <mu2>0.2</mu2>
    <material>Gazebo/Blue</material>
  </gazebo>
  <link name="grasper2_L">
    <visual>
      <geometry>
        <mesh filename="package://surgical_tools_description/meshes/grasper_2.dae" />
      </geometry>
      <origin rpy="0 0 0" xyz="-0.00680 -0.00904 0.00452" />
    </visual>

    <inertial>
      <origin rpy="0 0 0" xyz="-0.00680 -0.00904 0.00452" />
      <mass value="1" />
      <inertia ixx="0" ixy="0" ixz="0" iyy="0" iyz="0" izz="0" />
    </inertial>

    <collision>
      <geometry>
        <mesh filename="package://surgical_tools_description/meshes/grasper_2.dae" />
      </geometry>
      <surface>
        <contact>
          <ode>
            <kp>1000000.0</kp>
            <kd>1.0</kd>
            <mu1>0.2</mu1>
            <mu2>0.2</mu2>
            <minDepth>0.001</minDepth>

          </ode>
        </contact>
      </surface>
      <origin rpy="0 0 0" xyz="-0.00680 -0.00904 0.00452" />
    </collision>
  </link>


  <joint name="tool_roll_L" type="revolute">
    <axis xyz="-0.6012   -0.7460    0.2864" />
    <limit effort="1000.0" lower="-3.1415" upper="3.1415" velocity="0.5" />
    <origin rpy="0 0 0" xyz="0 0 0" />
    <parent link="link3_L" />
    <child link="instrument_shaft_L" />
  </joint>

  <joint name="wrist_joint_L" type="revolute">
    <axis xyz=" -0.5637    0.6523    0.5067" />
    <limit effort="1000.0" lower="-2" upper="2" velocity="0.5" />
    <origin rpy="0 0 0" xyz="0 0 0" />
    <parent link="instrument_shaft_L" />
    <child link="wrist_L" />
  </joint>

  <joint name="grasper_joint_1_L" type="revolute">
    <axis xyz="-0.5648    0.1427   -0.8128" />
    <limit effort="1000.0" lower="-2" upper="2" velocity=".5" />
    <origin rpy="0 0 0" xyz="0.00680 0.00904 -0.00452" />
    <parent link="wrist_L" />
    <child link="grasper1_L" />
  </joint>

  <joint name="grasper_joint_2_L" type="revolute">
    <axis xyz="0.5648    -0.1427   0.8128" />
    <limit effort="1000.0" lower="-2" upper="2" velocity=".5" />
    <origin rpy="0 0 0" xyz="0.00680 0.00904 -0.00452" />
    <parent link="wrist_L" />
    <child link="grasper2_L" />
  </joint>


  <link name="0_link">
    <gazebo reference="0_link">
      <turnGravityOff>true</turnGravityOff>
    </gazebo>
    <visual>
      <origin xyz="0 0 0" rpy="0 0 0" />
      <geometry>
        <box size="0.00001 0.00001 0.00001" />
      </geometry>
      <material name="Cyan">
        <color rgba="0 255 255 1.0" />
      </material>
    </visual>
    <inertial>
      <origin xyz="0 0 0" rpy="0 0 0" />
      <mass value="0.1" />
      <inertia ixx="0" ixy="0" ixz="0" iyy="0" iyz="0" izz="0" />
    </inertial>
  </link>
  <joint name="insertion_L" type="revolute">
    <axis xyz="0 0 0" />
    <limit effort="1000.0" lower="-2" upper="2" velocity=".5" />
    <origin rpy="1.904601 0.954344 -0.014100" xyz="0 0 0" />
    <parent link="0_link" />
    <child link="link3_L" />
  </joint>

</robot>